<?xml version="1.0" ?>
<!-- =================================================================================== -->
<!-- |    This document was autogenerated by xacro from cwego.xacro                    | -->
<!-- |    EDITING THIS FILE BY HAND IS NOT RECOMMENDED                                 | -->
<!-- =================================================================================== -->
<robot name="cwego">
  <!--Car Body-->
  <link name="base_link">
    <collision>
      <origin rpy="0 0 0" xyz="0 0 0.975"/>
      <geometry>
        <!--<box size="${base_length} ${base_width} ${base_height}"/>-->
        <mesh filename="package://vehicle/meshes/base_link.STL"/>
      </geometry>
    </collision>
    <visual>
      <origin rpy="0 0 0" xyz="0 0 0.975"/>
      <geometry>
        <mesh filename="package://vehicle/textures/body.dae"/>
        <!-- <box size="${base_length} ${base_width} ${base_height}"/>  -->

      </geometry>
    </visual>
  </link>
  <joint name="inertial_joint" type="fixed">
    <parent link="base_link"/>
    <child link="main_mass"/>
    <origin rpy="0 0 0" xyz="0 0 0.975"/>
  </joint>
  <link name="main_mass" type="fixed">
    <inertial>
      <origin rpy="0 0 0" xyz="0 0 0"/>
      <mass value="956"/>
      <inertia ixx="343" ixy="0.000000" ixz="0.000000" iyy="728" iyz="0.000000" izz="772"/>
    </inertial>
  </link>
  <!--Slider-->
  <joint name="slider_joint" type="prismatic">
    <parent link="base_link"/>
    <child link="slider"/>
    <origin rpy="0 1.5707963417948965 0" xyz="0 0 0.47595"/>
    <axis xyz="0 0 1"/>
    <limit effort="1000000.0" lower="-1.5" upper="1.5" velocity="10000.0"/>
  </joint>
  <link name="slider">
    <collision>
      <origin rpy="0 0 0" xyz="0 0 0"/>
      <geometry>
        <box size="0.3 0.4 0.4"/>
      </geometry>
    </collision>
    <visual>
      <origin rpy="0 0 1.5707963417948965" xyz="0 0 0"/>
      <geometry>
        <mesh filename="package://vehicle/textures/slider.dae"/>
        <!-- <box size="${slider_length} ${slider_width} ${slider_height}"/> -->
      </geometry>
    </visual>
    <inertial>
      <origin rpy="0 0 1.5707963417948965 " xyz="0 0 0"/>
      <mass value="10"/>
      <inertia ixx="0.9" ixy="0.000000" ixz="0.000000" iyy="1.6" iyz="0.000000" izz="1.8"/>
    </inertial>
  </link>
  <!--ML lift1-->
  <joint name="ml_lift1_joint" type="revolute">
    <parent link="slider"/>
    <child link="ml_lift1"/>
    <origin rpy="0 3.141592683589793 -1.5707963417948965" xyz="0 0.2 0"/>
    <axis xyz="0 0 1"/>
    <limit effort="1000000.0" lower="-0.785" upper="0.785" velocity="10000.0"/>
  </joint>
  <link name="ml_lift1">
    <collision>
      <origin rpy="0 1.5707963417948965 0" xyz="0.245 0 0"/>
      <geometry>
        <cylinder length="0.49" radius="0.05"/>
      </geometry>
    </collision>
    <visual>
      <origin rpy="0 1.5707963417948965 0" xyz="0.245 0 0"/>
      <geometry>
        <cylinder length="0.49" radius="0.05"/>
      </geometry>
    </visual>
    <inertial>
      <origin rpy="0 0 0" xyz="0 0 0"/>
      <mass value="5"/>
      <inertia ixx="0.012" ixy="0.000000" ixz="0.000000" iyy="0.025" iyz="0.000000" izz="0.012"/>
    </inertial>
  </link>
  <!--ML lift2-->
  <joint name="ml_lift2_joint" type="revolute">
    <parent link="ml_lift1"/>
    <child link="ml_lift2"/>
    <origin rpy="0 0  0" xyz="0.4925 0 0"/>
    <axis xyz="0 0 1"/>
    <limit effort="1000000.0" lower="-0.785" upper="0.785" velocity="10000.0"/>
  </joint>
  <link name="ml_lift2">
    <collision>
      <origin rpy="0 1.5707963417948965 0" xyz="0 0 0"/>
      <geometry>
        <cylinder length="0.005" radius="0.06"/>
      </geometry>
    </collision>
    <visual>
      <origin rpy="0 1.5707963417948965 0" xyz="0 0 0"/>
      <geometry>
        <cylinder length="0.005" radius="0.06"/>
      </geometry>
    </visual>
    <inertial>
      <origin rpy="0 0 0" xyz="0 0 0"/>
      <mass value="1"/>
      <inertia ixx="0.012" ixy="0.000000" ixz="0.000000" iyy="0.025" iyz="0.000000" izz="0.012"/>
    </inertial>
  </link>
  <!--ML steer-->
  <joint name="ml_steer_joint" type="revolute">
    <parent link="ml_lift2"/>
    <child link="ml_steer"/>
    <origin rpy="1.5707963417948965 0  0" xyz="0 0 0"/>
    <axis xyz="0 0 1"/>
    <limit effort="1000000.0" lower="-0.785" upper="0.785" velocity="10000.0"/>
  </joint>
  <link name="ml_steer">
    <collision>
      <origin rpy="0 1.5707963417948965 0" xyz="0 0 0"/>
      <geometry>
        <cylinder length="0.005" radius="0.08"/>
      </geometry>
    </collision>
    <visual>
      <origin rpy="0 1.5707963417948965 0" xyz="0 0 0"/>
      <geometry>
        <cylinder length="0.005" radius="0.08"/>
      </geometry>
    </visual>
    <inertial>
      <origin rpy="0 0 0" xyz="0 0 0"/>
      <mass value="5"/>
      <inertia ixx="0.012" ixy="0.000000" ixz="0.000000" iyy="0.025" iyz="0.000000" izz="0.012"/>
    </inertial>
  </link>
  <!--ML wheel-->
  <joint name="ml_wheel_joint" type="continuous">
    <parent link="ml_steer"/>
    <child link="ml_wheel"/>
    <origin rpy="0 -1.5707963417948965  0" xyz="0.165 0 0"/>
    <axis xyz="0 0 1"/>
    <limit effort="1000000" velocity="10000"/>
    <joint_properties damping="0.0" friction="0.0"/>
  </joint>
  <link name="ml_wheel">
    <collision>
      <origin rpy="3.141592683589793 0 0" xyz="0 0 0"/>
      <geometry>
        <cylinder length="0.255" radius="0.463"/>
      </geometry>
    </collision>
    <visual>
      <origin rpy="3.141592683589793 0 0" xyz="0 0 0"/>
      <geometry>
        <mesh filename="package://vehicle/textures/wheel.dae"/>
        <!--<cylinder length="${tyre_length}" radius="${tyre_radius}"/>-->
      </geometry>
    </visual>
    <inertial>
      <origin rpy="0 0 0" xyz="0 0 0"/>
      <mass value="20"/>
      <inertia ixx="0.5" ixy="0.000000" ixz="0.000000" iyy="0.9" iyz="0.000000" izz="0.5"/>
    </inertial>
  </link>
  <!--MR lift1-->
  <joint name="mr_lift1_joint" type="revolute">
    <parent link="slider"/>
    <child link="mr_lift1"/>
    <origin rpy="0 0 -1.5707963417948965" xyz="0 -0.2 0"/>
    <axis xyz="0 0 1"/>
    <limit effort="1000000.0" lower="-0.785" upper="0.785" velocity="10000.0"/>
  </joint>
  <link name="mr_lift1">
    <collision>
      <origin rpy="0 1.5707963417948965 0" xyz="0.245 0 0"/>
      <geometry>
        <cylinder length="0.49" radius="0.05"/>
      </geometry>
    </collision>
    <visual>
      <origin rpy="0 1.5707963417948965 0" xyz="0.245 0 0"/>
      <geometry>
        <cylinder length="0.49" radius="0.05"/>
      </geometry>
    </visual>
    <inertial>
      <origin rpy="0 0 0" xyz="0 0 0"/>
      <mass value="5"/>
      <inertia ixx="0.012" ixy="0.000000" ixz="0.000000" iyy="0.025" iyz="0.000000" izz="0.012"/>
    </inertial>
  </link>
  <!--MR lift2-->
  <joint name="mr_lift2_joint" type="revolute">
    <parent link="mr_lift1"/>
    <child link="mr_lift2"/>
    <origin rpy="0 0  0" xyz="0.4925 0 0"/>
    <axis xyz="0 0 1"/>
    <limit effort="1000000.0" lower="-0.785" upper="0.785" velocity="10000.0"/>
  </joint>
  <link name="mr_lift2">
    <collision>
      <origin rpy="0 1.5707963417948965 0" xyz="0 0 0"/>
      <geometry>
        <cylinder length="0.005" radius="0.06"/>
      </geometry>
    </collision>
    <visual>
      <origin rpy="0 1.5707963417948965 0" xyz="0 0 0"/>
      <geometry>
        <cylinder length="0.005" radius="0.06"/>
      </geometry>
    </visual>
    <inertial>
      <origin rpy="0 0 0" xyz="0 0 0"/>
      <mass value="1"/>
      <inertia ixx="0.012" ixy="0.000000" ixz="0.000000" iyy="0.025" iyz="0.000000" izz="0.012"/>
    </inertial>
  </link>
  <!--MR steer-->
  <joint name="mr_steer_joint" type="revolute">
    <parent link="mr_lift2"/>
    <child link="mr_steer"/>
    <origin rpy="1.5707963417948965 0  0" xyz="0 0 0"/>
    <axis xyz="0 0 1"/>
    <limit effort="1000000.0" lower="-0.785" upper="0.785" velocity="10000.0"/>
  </joint>
  <link name="mr_steer">
    <collision>
      <origin rpy="0 1.5707963417948965 0" xyz="0 0 0"/>
      <geometry>
        <cylinder length="0.005" radius="0.08"/>
      </geometry>
    </collision>
    <visual>
      <origin rpy="0 1.5707963417948965 0" xyz="0 0 0"/>
      <geometry>
        <cylinder length="0.005" radius="0.08"/>
      </geometry>
    </visual>
    <inertial>
      <origin rpy="0 0 0" xyz="0 0 0"/>
      <mass value="5"/>
      <inertia ixx="0.012" ixy="0.000000" ixz="0.000000" iyy="0.025" iyz="0.000000" izz="0.012"/>
    </inertial>
  </link>
  <!--MR wheel-->
  <joint name="mr_wheel_joint" type="continuous">
    <parent link="mr_steer"/>
    <child link="mr_wheel"/>
    <origin rpy="0 1.5707963417948965  0" xyz="0.165 0 0"/>
    <axis xyz="0 0 1"/>
    <limit effort="1000000" velocity="10000"/>
    <joint_properties damping="0.0" friction="0.0"/>
  </joint>
  <link name="mr_wheel">
    <collision>
      <origin rpy="0 0 0" xyz="0 0 0"/>
      <geometry>
        <cylinder length="0.255" radius="0.463"/>
      </geometry>
    </collision>
    <visual>
      <origin rpy="0 0 0" xyz="0 0 0"/>
      <geometry>
        <mesh filename="package://vehicle/textures/wheel.dae"/>
        <!--<cylinder length="${tyre_length}" radius="${tyre_radius}"/>-->
      </geometry>
    </visual>
    <inertial>
      <origin rpy="0 0 0" xyz="0 0 0"/>
      <mass value="20"/>
      <inertia ixx="0.5" ixy="0.000000" ixz="0.000000" iyy="0.9" iyz="0.000000" izz="0.5"/>
    </inertial>
  </link>
  <!-- ***************************************FL************************************* -->
  <!--FL lift1-->
  <joint name="fl_lift1_joint" type="revolute">
    <parent link="base_link"/>
    <child link="fl_lift1"/>
    <origin rpy="0 0 1.5707963417948965" xyz="1.7 0.2 0.47595"/>
    <axis xyz="0 1 0"/>
    <limit effort="1000000.0" lower="-0.785" upper="0.785" velocity="10000.0"/>
  </joint>
  <link name="fl_lift1">
    <collision>
      <origin rpy="0 1.5707963417948965 0" xyz="0.245 0 0"/>
      <geometry>
        <cylinder length="0.49" radius="0.05"/>
      </geometry>
    </collision>
    <visual>
      <origin rpy="0 1.5707963417948965 0" xyz="0.245 0 0"/>
      <geometry>
        <cylinder length="0.49" radius="0.05"/>
      </geometry>
    </visual>
    <inertial>
      <origin rpy="0 0 0" xyz="0 0 0"/>
      <mass value="5"/>
      <inertia ixx="0.012" ixy="0.000000" ixz="0.000000" iyy="0.025" iyz="0.000000" izz="0.012"/>
    </inertial>
  </link>
  <!--FL lift2-->
  <joint name="fl_lift2_joint" type="revolute">
    <parent link="fl_lift1"/>
    <child link="fl_lift2"/>
    <origin rpy="0 0  0" xyz="0.4925 0 0"/>
    <axis xyz="0 1 0"/>
    <limit effort="1000000.0" lower="-0.785" upper="0.785" velocity="10000.0"/>
  </joint>
  <link name="fl_lift2">
    <collision>
      <origin rpy="0 1.5707963417948965 0" xyz="0 0 0"/>
      <geometry>
        <cylinder length="0.005" radius="0.06"/>
      </geometry>
    </collision>
    <visual>
      <origin rpy="0 1.5707963417948965 0" xyz="0 0 0"/>
      <geometry>
        <cylinder length="0.005" radius="0.06"/>
      </geometry>
    </visual>
    <inertial>
      <origin rpy="0 0 0" xyz="0 0 0"/>
      <mass value="1"/>
      <inertia ixx="0.012" ixy="0.000000" ixz="0.000000" iyy="0.025" iyz="0.000000" izz="0.012"/>
    </inertial>
  </link>
  <!--FL steer-->
  <joint name="fl_steer_joint" type="revolute">
    <parent link="fl_lift2"/>
    <child link="fl_steer"/>
    <origin rpy="1.5707963417948965 0  0" xyz="0 0 0"/>
    <axis xyz="0 1 0"/>
    <limit effort="1000000.0" lower="-0.785" upper="0.785" velocity="10000.0"/>
  </joint>
  <link name="fl_steer">
    <collision>
      <origin rpy="0 1.5707963417948965 0" xyz="0 0 0"/>
      <geometry>
        <cylinder length="0.005" radius="0.08"/>
      </geometry>
    </collision>
    <visual>
      <origin rpy="0 1.5707963417948965 0" xyz="0 0 0"/>
      <geometry>
        <cylinder length="0.005" radius="0.08"/>
      </geometry>
    </visual>
    <inertial>
      <origin rpy="0 0 0" xyz="0 0 0"/>
      <mass value="5"/>
      <inertia ixx="0.012" ixy="0.000000" ixz="0.000000" iyy="0.025" iyz="0.000000" izz="0.012"/>
    </inertial>
  </link>
  <!--FL wheel-->
  <joint name="fl_wheel_joint" type="continuous">
    <parent link="fl_steer"/>
    <child link="fl_wheel"/>
    <origin rpy="0 -1.5707963417948965  0" xyz="0.165 0 0"/>
    <axis xyz="0 0 1"/>
    <limit effort="1000000" velocity="10000"/>
    <joint_properties damping="0.0" friction="0.0"/>
  </joint>
  <link name="fl_wheel">
    <collision>
      <origin rpy="3.141592683589793 0 0" xyz="0 0 0"/>
      <geometry>
        <cylinder length="0.255" radius="0.463"/>
      </geometry>
    </collision>
    <visual>
      <origin rpy="3.141592683589793 0 0" xyz="0 0 0"/>
      <geometry>
        <mesh filename="package://vehicle/textures/wheel.dae"/>
        <!--<cylinder length="${tyre_length}" radius="${tyre_radius}"/>-->
      </geometry>
    </visual>
    <inertial>
      <origin rpy="0 0 0" xyz="0 0 0"/>
      <mass value="20"/>
      <inertia ixx="0.5" ixy="0.000000" ixz="0.000000" iyy="0.9" iyz="0.000000" izz="0.5"/>
    </inertial>
  </link>
  <!-- ***************************************RL************************************* -->
  <!--RL lift1-->
  <joint name="rl_lift1_joint" type="revolute">
    <parent link="base_link"/>
    <child link="rl_lift1"/>
    <origin rpy="0 0 1.5707963417948965" xyz="-1.7 0.2 0.47595"/>
    <axis xyz="0 1 0"/>
    <limit effort="1000000.0" lower="-0.785" upper="0.785" velocity="10000.0"/>
  </joint>
  <link name="rl_lift1">
    <collision>
      <origin rpy="0 1.5707963417948965 0" xyz="0.245 0 0"/>
      <geometry>
        <cylinder length="0.49" radius="0.05"/>
      </geometry>
    </collision>
    <visual>
      <origin rpy="0 1.5707963417948965 0" xyz="0.245 0 0"/>
      <geometry>
        <cylinder length="0.49" radius="0.05"/>
      </geometry>
    </visual>
    <inertial>
      <origin rpy="0 0 0" xyz="0 0 0"/>
      <mass value="5"/>
      <inertia ixx="0.012" ixy="0.000000" ixz="0.000000" iyy="0.025" iyz="0.000000" izz="0.012"/>
    </inertial>
  </link>
  <!--RL lift2-->
  <joint name="rl_lift2_joint" type="revolute">
    <parent link="rl_lift1"/>
    <child link="rl_lift2"/>
    <origin rpy="0 0  0" xyz="0.4925 0 0"/>
    <axis xyz="0 1 0"/>
    <limit effort="1000000.0" lower="-0.785" upper="0.785" velocity="10000.0"/>
  </joint>
  <link name="rl_lift2">
    <collision>
      <origin rpy="0 1.5707963417948965 0" xyz="0 0 0"/>
      <geometry>
        <cylinder length="0.005" radius="0.06"/>
      </geometry>
    </collision>
    <visual>
      <origin rpy="0 1.5707963417948965 0" xyz="0 0 0"/>
      <geometry>
        <cylinder length="0.005" radius="0.06"/>
      </geometry>
    </visual>
    <inertial>
      <origin rpy="0 0 0" xyz="0 0 0"/>
      <mass value="1"/>
      <inertia ixx="0.012" ixy="0.000000" ixz="0.000000" iyy="0.025" iyz="0.000000" izz="0.012"/>
    </inertial>
  </link>
  <!--RL steer-->
  <joint name="rl_steer_joint" type="revolute">
    <parent link="rl_lift2"/>
    <child link="rl_steer"/>
    <origin rpy="1.5707963417948965 0  0" xyz="0 0 0"/>
    <axis xyz="0 1 0"/>
    <limit effort="1000000.0" lower="-0.785" upper="0.785" velocity="10000.0"/>
  </joint>
  <link name="rl_steer">
    <collision>
      <origin rpy="0 1.5707963417948965 0" xyz="0 0 0"/>
      <geometry>
        <cylinder length="0.005" radius="0.08"/>
      </geometry>
    </collision>
    <visual>
      <origin rpy="0 1.5707963417948965 0" xyz="0 0 0"/>
      <geometry>
        <cylinder length="0.005" radius="0.08"/>
      </geometry>
    </visual>
    <inertial>
      <origin rpy="0 0 0" xyz="0 0 0"/>
      <mass value="5"/>
      <inertia ixx="0.012" ixy="0.000000" ixz="0.000000" iyy="0.025" iyz="0.000000" izz="0.012"/>
    </inertial>
  </link>
  <!--RL wheel-->
  <joint name="rl_wheel_joint" type="continuous">
    <parent link="rl_steer"/>
    <child link="rl_wheel"/>
    <origin rpy="0 -1.5707963417948965  0" xyz="0.165 0 0"/>
    <axis xyz="0 0 1"/>
    <limit effort="1000000" velocity="10000"/>
    <joint_properties damping="0.0" friction="0.0"/>
  </joint>
  <link name="rl_wheel">
    <collision>
      <origin rpy="3.141592683589793 0 0" xyz="0 0 0"/>
      <geometry>
        <cylinder length="0.255" radius="0.463"/>
      </geometry>
    </collision>
    <visual>
      <origin rpy="3.141592683589793 0 0" xyz="0 0 0"/>
      <geometry>
        <mesh filename="package://vehicle/textures/wheel.dae"/>
        <!--<cylinder length="${tyre_length}" radius="${tyre_radius}"/>-->
      </geometry>
    </visual>
    <inertial>
      <origin rpy="0 0 0" xyz="0 0 0"/>
      <mass value="20"/>
      <inertia ixx="0.5" ixy="0.000000" ixz="0.000000" iyy="0.9" iyz="0.000000" izz="0.5"/>
    </inertial>
  </link>
  <!-- ***************************************FR************************************* -->
  <!--FR lift1-->
  <joint name="fr_lift1_joint" type="revolute">
    <parent link="base_link"/>
    <child link="fr_lift1"/>
    <origin rpy="0 0 -1.5707963417948965" xyz="1.7 -0.2 0.47595"/>
    <axis xyz="0 1 0"/>
    <limit effort="1000000.0" lower="-0.785" upper="0.785" velocity="10000.0"/>
  </joint>
  <link name="fr_lift1">
    <collision>
      <origin rpy="0 1.5707963417948965 0" xyz="0.245 0 0"/>
      <geometry>
        <cylinder length="0.49" radius="0.05"/>
      </geometry>
    </collision>
    <visual>
      <origin rpy="0 1.5707963417948965 0" xyz="0.245 0 0"/>
      <geometry>
        <cylinder length="0.49" radius="0.05"/>
      </geometry>
    </visual>
    <inertial>
      <origin rpy="0 0 0" xyz="0 0 0"/>
      <mass value="5"/>
      <inertia ixx="0.012" ixy="0.000000" ixz="0.000000" iyy="0.025" iyz="0.000000" izz="0.012"/>
    </inertial>
  </link>
  <!--FR lift2-->
  <joint name="fr_lift2_joint" type="revolute">
    <parent link="fr_lift1"/>
    <child link="fr_lift2"/>
    <origin rpy="0 0  0" xyz="0.4925 0 0"/>
    <axis xyz="0 1 0"/>
    <limit effort="1000000.0" lower="-0.785" upper="0.785" velocity="10000.0"/>
  </joint>
  <link name="fr_lift2">
    <collision>
      <origin rpy="0 1.5707963417948965 0" xyz="0 0 0"/>
      <geometry>
        <cylinder length="0.005" radius="0.06"/>
      </geometry>
    </collision>
    <visual>
      <origin rpy="0 1.5707963417948965 0" xyz="0 0 0"/>
      <geometry>
        <cylinder length="0.005" radius="0.06"/>
      </geometry>
    </visual>
    <inertial>
      <origin rpy="0 0 0" xyz="0 0 0"/>
      <mass value="1"/>
      <inertia ixx="0.012" ixy="0.000000" ixz="0.000000" iyy="0.025" iyz="0.000000" izz="0.012"/>
    </inertial>
  </link>
  <!--FR steer-->
  <joint name="fr_steer_joint" type="revolute">
    <parent link="fr_lift2"/>
    <child link="fr_steer"/>
    <origin rpy="1.5707963417948965 0  0" xyz="0 0 0"/>
    <axis xyz="0 1 0"/>
    <limit effort="1000000.0" lower="-0.785" upper="0.785" velocity="10000.0"/>
  </joint>
  <link name="fr_steer">
    <collision>
      <origin rpy="0 1.5707963417948965 0" xyz="0 0 0"/>
      <geometry>
        <cylinder length="0.005" radius="0.08"/>
      </geometry>
    </collision>
    <visual>
      <origin rpy="0 1.5707963417948965 0" xyz="0 0 0"/>
      <geometry>
        <cylinder length="0.005" radius="0.08"/>
      </geometry>
    </visual>
    <inertial>
      <origin rpy="0 0 0" xyz="0 0 0"/>
      <mass value="5"/>
      <inertia ixx="0.012" ixy="0.000000" ixz="0.000000" iyy="0.025" iyz="0.000000" izz="0.012"/>
    </inertial>
  </link>
  <!--FR wheel-->
  <joint name="fr_wheel_joint" type="continuous">
    <parent link="fr_steer"/>
    <child link="fr_wheel"/>
    <origin rpy="0 1.5707963417948965  0" xyz="0.165 0 0"/>
    <axis xyz="0 0 1"/>
    <limit effort="1000000" velocity="10000"/>
    <joint_properties damping="0.0" friction="0.0"/>
  </joint>
  <link name="fr_wheel">
    <collision>
      <origin rpy="0 0 0" xyz="0 0 0"/>
      <geometry>
        <cylinder length="0.255" radius="0.463"/>
      </geometry>
    </collision>
    <visual>
      <origin rpy="0 0 0" xyz="0 0 0"/>
      <geometry>
        <mesh filename="package://vehicle/textures/wheel.dae"/>
        <!--<cylinder length="${tyre_length}" radius="${tyre_radius}"/>-->
      </geometry>
    </visual>
    <inertial>
      <origin rpy="0 0 0" xyz="0 0 0"/>
      <mass value="20"/>
      <inertia ixx="0.5" ixy="0.000000" ixz="0.000000" iyy="0.9" iyz="0.000000" izz="0.5"/>
    </inertial>
  </link>
  <!-- ***************************************RR************************************* -->
  <!--RR lift1-->
  <joint name="rr_lift1_joint" type="revolute">
    <parent link="base_link"/>
    <child link="rr_lift1"/>
    <origin rpy="0 0 -1.5707963417948965" xyz="-1.7 -0.2 0.47595"/>
    <axis xyz="0 1 0"/>
    <limit effort="1000000.0" lower="-0.785" upper="0.785" velocity="10000.0"/>
  </joint>
  <link name="rr_lift1">
    <collision>
      <origin rpy="0 1.5707963417948965 0" xyz="0.245 0 0"/>
      <geometry>
        <cylinder length="0.49" radius="0.05"/>
      </geometry>
    </collision>
    <visual>
      <origin rpy="0 1.5707963417948965 0" xyz="0.245 0 0"/>
      <geometry>
        <cylinder length="0.49" radius="0.05"/>
      </geometry>
    </visual>
    <inertial>
      <origin rpy="0 0 0" xyz="0 0 0"/>
      <mass value="5"/>
      <inertia ixx="0.012" ixy="0.000000" ixz="0.000000" iyy="0.025" iyz="0.000000" izz="0.012"/>
    </inertial>
  </link>
  <!--RR lift2-->
  <joint name="rr_lift2_joint" type="revolute">
    <parent link="rr_lift1"/>
    <child link="rr_lift2"/>
    <origin rpy="0 0  0" xyz="0.4925 0 0"/>
    <axis xyz="0 1 0"/>
    <limit effort="1000000.0" lower="-0.785" upper="0.785" velocity="10000.0"/>
  </joint>
  <link name="rr_lift2">
    <collision>
      <origin rpy="0 1.5707963417948965 0" xyz="0 0 0"/>
      <geometry>
        <cylinder length="0.005" radius="0.06"/>
      </geometry>
    </collision>
    <visual>
      <origin rpy="0 1.5707963417948965 0" xyz="0 0 0"/>
      <geometry>
        <cylinder length="0.005" radius="0.06"/>
      </geometry>
    </visual>
    <inertial>
      <origin rpy="0 0 0" xyz="0 0 0"/>
      <mass value="1"/>
      <inertia ixx="0.012" ixy="0.000000" ixz="0.000000" iyy="0.025" iyz="0.000000" izz="0.012"/>
    </inertial>
  </link>
  <!--RR steer-->
  <joint name="rr_steer_joint" type="revolute">
    <parent link="rr_lift2"/>
    <child link="rr_steer"/>
    <origin rpy="1.5707963417948965 0  0" xyz="0 0 0"/>
    <axis xyz="0 1 0"/>
    <limit effort="1000000.0" lower="-0.785" upper="0.785" velocity="10000.0"/>
  </joint>
  <link name="rr_steer">
    <collision>
      <origin rpy="0 1.5707963417948965 0" xyz="0 0 0"/>
      <geometry>
        <cylinder length="0.005" radius="0.08"/>
      </geometry>
    </collision>
    <visual>
      <origin rpy="0 1.5707963417948965 0" xyz="0 0 0"/>
      <geometry>
        <cylinder length="0.005" radius="0.08"/>
      </geometry>
    </visual>
    <inertial>
      <origin rpy="0 0 0" xyz="0 0 0"/>
      <mass value="5"/>
      <inertia ixx="0.012" ixy="0.000000" ixz="0.000000" iyy="0.025" iyz="0.000000" izz="0.012"/>
    </inertial>
  </link>
  <!--RR wheel-->
  <joint name="rr_wheel_joint" type="continuous">
    <parent link="rr_steer"/>
    <child link="rr_wheel"/>
    <origin rpy="0 1.5707963417948965  0" xyz="0.165 0 0"/>
    <axis xyz="0 0 1"/>
    <limit effort="1000000" velocity="10000"/>
    <joint_properties damping="0.0" friction="0.0"/>
  </joint>
  <link name="rr_wheel">
    <collision>
      <origin rpy="0 0 0" xyz="0 0 0"/>
      <geometry>
        <cylinder length="0.255" radius="0.463"/>
      </geometry>
    </collision>
    <visual>
      <origin rpy="0 0 0" xyz="0 0 0"/>
      <geometry>
        <mesh filename="package://vehicle/textures/wheel.dae"/>
        <!--<cylinder length="${tyre_length}" radius="${tyre_radius}"/>-->
      </geometry>
    </visual>
    <inertial>
      <origin rpy="0 0 0" xyz="0 0 0"/>
      <mass value="20"/>
      <inertia ixx="0.5" ixy="0.000000" ixz="0.000000" iyy="0.9" iyz="0.000000" izz="0.5"/>
    </inertial>
  </link>
  <!--<cylinder length="${tyre_length}" radius="${tyre_radius}"/>-->
  <joint name="lidar_joint" type="fixed">
    <origin rpy="0 0 0" xyz="0 0 1.55"/>
    <parent link="base_link"/>
    <child link="laser_link"/>
  </joint>
  <link name="laser_link">
    <inertial>
      <mass value="0.1"/>
      <origin xyz="0 0 0"/>
      <inertia ixx="0.01" ixy="0.0" ixz="0.0" iyy="0.01" iyz="0.0" izz="0.01"/>
    </inertial>
    <visual>
      <origin rpy="0 0 0" xyz=" 0 0 0 "/>
      <geometry>
        <cylinder length="0.3" radius="0.2"/>
      </geometry>
    </visual>
    <collision>
      <origin rpy="0 0 0" xyz="0.0 0.0 0.0"/>
      <geometry>
        <cylinder length="0.3" radius="0.2"/>
      </geometry>
    </collision>
  </link>
  <joint name="camera_joint" type="fixed">
    <origin rpy="0 0 0" xyz="2.1 0 1.0"/>
    <parent link="base_link"/>
    <child link="camera_link"/>
  </joint>
  <link name="camera_link">
    <inertial>
      <mass value="0.1"/>
      <origin xyz="0 0 0"/>
      <inertia ixx="0.01" ixy="0.0" ixz="0.0" iyy="0.01" iyz="0.0" izz="0.01"/>
    </inertial>
    <visual>
      <origin rpy="0 0 0" xyz=" 0 0 0 "/>
      <geometry>
        <box size="0.1 0.2 0.2"/>
      </geometry>
    </visual>
    <collision>
      <origin rpy="0 0 0" xyz="0.0 0.0 0.0"/>
      <geometry>
        <box size="0.1 0.2 0.2"/>
      </geometry>
    </collision>
  </link>
  <cwego_base/>
</robot>
